2023-01-08 12:13:01,508 - py.warnings - WARNING - /Users/k9/.pyenv/versions/3.9.11/envs/kedro-on-aws/lib/python3.9/site-packages/kedro/framework/context/context.py:339: UserWarning: Credentials not found in your Kedro project config.
No files found in ['/Users/k9/kedro-on-aws/conf/base', '/Users/k9/kedro-on-aws/conf/local'] matching the glob pattern(s): ['credentials*', 'credentials*/**', '**/credentials*']
  warn(f"Credentials not found in your Kedro project config.\n{str(exc)}")

2023-01-08 12:13:01,524 - Comm - ERROR - No such comm target registered: jupyter.widget.control
2023-01-08 12:13:01,527 - Comm - WARNING - No such comm: 09025f9e-5a15-4f2f-8949-48f483b41cee
2023-01-08 12:17:31,043 - py.warnings - WARNING - /Users/k9/.pyenv/versions/3.9.11/envs/kedro-on-aws/lib/python3.9/site-packages/kedro/framework/context/context.py:339: UserWarning: Credentials not found in your Kedro project config.
No files found in ['/Users/k9/kedro-on-aws/conf/base', '/Users/k9/kedro-on-aws/conf/local'] matching the glob pattern(s): ['credentials*', 'credentials*/**', '**/credentials*']
  warn(f"Credentials not found in your Kedro project config.\n{str(exc)}")

2023-01-08 12:17:31,541 - py.warnings - WARNING - /Users/k9/.pyenv/versions/3.9.11/envs/kedro-on-aws/lib/python3.9/site-packages/kedro/framework/project/__init__.py:330: UserWarning: An error occurred while importing the 'iris.pipeline' module. Nothing defined therein will be returned by 'find_pipelines'.

Traceback (most recent call last):
  File "/Users/k9/.pyenv/versions/3.9.11/envs/kedro-on-aws/lib/python3.9/site-packages/kedro/framework/project/__init__.py", line 327, in find_pipelines
    pipeline_module = importlib.import_module(pipeline_module_name)
  File "/Users/k9/.pyenv/versions/3.9.11/lib/python3.9/importlib/__init__.py", line 127, in import_module
    return _bootstrap._gcd_import(name[level:], package, level)
  File "<frozen importlib._bootstrap>", line 1030, in _gcd_import
  File "<frozen importlib._bootstrap>", line 1007, in _find_and_load
  File "<frozen importlib._bootstrap>", line 986, in _find_and_load_unlocked
  File "<frozen importlib._bootstrap>", line 680, in _load_unlocked
  File "<frozen importlib._bootstrap_external>", line 850, in exec_module
  File "<frozen importlib._bootstrap>", line 228, in _call_with_frames_removed
  File "/Users/k9/kedro-on-aws/src/iris/pipeline.py", line 8, in <module>
    from .nodes import make_predictions, report_accuracy, split_data
ImportError: cannot import name 'make_predictions' from 'iris.nodes' (/Users/k9/kedro-on-aws/src/iris/nodes.py)

  warnings.warn(

2023-01-08 12:17:33,284 - Comm - ERROR - No such comm target registered: jupyter.widget.control
2023-01-08 12:17:33,288 - Comm - WARNING - No such comm: ffb8f74c-7e19-4ac5-8bf2-e305f251c45b
2023-01-08 12:19:17,153 - py.warnings - WARNING - /Users/k9/.pyenv/versions/3.9.11/envs/kedro-on-aws/lib/python3.9/site-packages/kedro/framework/context/context.py:339: UserWarning: Credentials not found in your Kedro project config.
No files found in ['/Users/k9/kedro-on-aws/conf/base', '/Users/k9/kedro-on-aws/conf/local'] matching the glob pattern(s): ['credentials*', 'credentials*/**', '**/credentials*']
  warn(f"Credentials not found in your Kedro project config.\n{str(exc)}")

2023-01-08 12:19:17,349 - py.warnings - WARNING - /Users/k9/.pyenv/versions/3.9.11/envs/kedro-on-aws/lib/python3.9/site-packages/kedro/framework/project/__init__.py:330: UserWarning: An error occurred while importing the 'iris.pipeline' module. Nothing defined therein will be returned by 'find_pipelines'.

Traceback (most recent call last):
  File "/Users/k9/.pyenv/versions/3.9.11/envs/kedro-on-aws/lib/python3.9/site-packages/kedro/framework/project/__init__.py", line 327, in find_pipelines
    pipeline_module = importlib.import_module(pipeline_module_name)
  File "/Users/k9/.pyenv/versions/3.9.11/lib/python3.9/importlib/__init__.py", line 127, in import_module
    return _bootstrap._gcd_import(name[level:], package, level)
  File "<frozen importlib._bootstrap>", line 1030, in _gcd_import
  File "<frozen importlib._bootstrap>", line 1007, in _find_and_load
  File "<frozen importlib._bootstrap>", line 986, in _find_and_load_unlocked
  File "<frozen importlib._bootstrap>", line 680, in _load_unlocked
  File "<frozen importlib._bootstrap_external>", line 850, in exec_module
  File "<frozen importlib._bootstrap>", line 228, in _call_with_frames_removed
  File "/Users/k9/kedro-on-aws/src/iris/pipeline.py", line 8, in <module>
    from .nodes import make_predictions, report_accuracy, split_data
ImportError: cannot import name 'make_predictions' from 'iris.nodes' (/Users/k9/kedro-on-aws/src/iris/nodes.py)

  warnings.warn(

2023-01-08 12:19:20,660 - py.warnings - WARNING - /Users/k9/.pyenv/versions/3.9.11/envs/kedro-on-aws/lib/python3.9/site-packages/kedro/framework/context/context.py:339: UserWarning: Credentials not found in your Kedro project config.
No files found in ['/Users/k9/kedro-on-aws/conf/base', '/Users/k9/kedro-on-aws/conf/local'] matching the glob pattern(s): ['credentials*', 'credentials*/**', '**/credentials*']
  warn(f"Credentials not found in your Kedro project config.\n{str(exc)}")

2023-01-08 12:19:20,664 - kedro.ipython - INFO - Kedro project iris
2023-01-08 12:19:20,665 - kedro.ipython - INFO - Defined global variable 'context', 'session', 'catalog' and 'pipelines'
2023-01-08 12:19:20,690 - Comm - ERROR - No such comm target registered: jupyter.widget.control
2023-01-08 12:19:20,692 - Comm - WARNING - No such comm: 3892c8c2-2701-4599-bd16-fa002c4454c6
2023-01-08 12:20:07,271 - kedro.io.data_catalog - INFO - Loading data from 'transactions' (AthenaQueryDataSet)...
2023-01-08 12:33:37,774 - Comm - ERROR - No such comm target registered: jupyter.widget.control
2023-01-08 12:33:37,780 - Comm - WARNING - No such comm: 5015ad38-3ec0-442b-ad5c-0fdf253ce31c
2023-01-08 12:34:00,327 - kedro.io.data_catalog - INFO - Loading data from 'transactions' (AthenaQueryDataSet)...
2023-01-08 12:36:06,652 - py.warnings - WARNING - /Users/k9/.pyenv/versions/3.9.11/envs/kedro-on-aws/lib/python3.9/site-packages/kedro/framework/context/context.py:339: UserWarning: Credentials not found in your Kedro project config.
No files found in ['/Users/k9/kedro-on-aws/conf/base', '/Users/k9/kedro-on-aws/conf/local'] matching the glob pattern(s): ['credentials*', 'credentials*/**', '**/credentials*']
  warn(f"Credentials not found in your Kedro project config.\n{str(exc)}")

2023-01-08 12:36:06,855 - py.warnings - WARNING - /Users/k9/.pyenv/versions/3.9.11/envs/kedro-on-aws/lib/python3.9/site-packages/kedro/framework/project/__init__.py:330: UserWarning: An error occurred while importing the 'iris.pipeline' module. Nothing defined therein will be returned by 'find_pipelines'.

Traceback (most recent call last):
  File "/Users/k9/.pyenv/versions/3.9.11/envs/kedro-on-aws/lib/python3.9/site-packages/kedro/framework/project/__init__.py", line 327, in find_pipelines
    pipeline_module = importlib.import_module(pipeline_module_name)
  File "/Users/k9/.pyenv/versions/3.9.11/lib/python3.9/importlib/__init__.py", line 127, in import_module
    return _bootstrap._gcd_import(name[level:], package, level)
  File "<frozen importlib._bootstrap>", line 1030, in _gcd_import
  File "<frozen importlib._bootstrap>", line 1007, in _find_and_load
  File "<frozen importlib._bootstrap>", line 986, in _find_and_load_unlocked
  File "<frozen importlib._bootstrap>", line 680, in _load_unlocked
  File "<frozen importlib._bootstrap_external>", line 850, in exec_module
  File "<frozen importlib._bootstrap>", line 228, in _call_with_frames_removed
  File "/Users/k9/kedro-on-aws/src/iris/pipeline.py", line 8, in <module>
    from .nodes import make_predictions, report_accuracy, split_data
ImportError: cannot import name 'make_predictions' from 'iris.nodes' (/Users/k9/kedro-on-aws/src/iris/nodes.py)

  warnings.warn(

2023-01-08 12:36:10,372 - py.warnings - WARNING - /Users/k9/.pyenv/versions/3.9.11/envs/kedro-on-aws/lib/python3.9/site-packages/kedro/framework/context/context.py:339: UserWarning: Credentials not found in your Kedro project config.
No files found in ['/Users/k9/kedro-on-aws/conf/base', '/Users/k9/kedro-on-aws/conf/local'] matching the glob pattern(s): ['credentials*', 'credentials*/**', '**/credentials*']
  warn(f"Credentials not found in your Kedro project config.\n{str(exc)}")

2023-01-08 12:36:10,376 - kedro.ipython - INFO - Kedro project iris
2023-01-08 12:36:10,377 - kedro.ipython - INFO - Defined global variable 'context', 'session', 'catalog' and 'pipelines'
2023-01-08 12:36:10,403 - Comm - ERROR - No such comm target registered: jupyter.widget.control
2023-01-08 12:36:10,406 - Comm - WARNING - No such comm: 0ad434e6-e7bd-4b17-b0f2-1a1ae5bff946
2023-01-08 12:36:12,126 - kedro.io.data_catalog - INFO - Loading data from 'transactions' (AthenaQueryDataSet)...
2023-01-08 12:58:06,486 - py.warnings - WARNING - /Users/k9/.pyenv/versions/3.9.11/envs/kedro-on-aws/lib/python3.9/site-packages/kedro/framework/context/context.py:339: UserWarning: Credentials not found in your Kedro project config.
No files found in ['/Users/k9/kedro-on-aws/conf/base', '/Users/k9/kedro-on-aws/conf/local'] matching the glob pattern(s): ['credentials*', 'credentials*/**', '**/credentials*']
  warn(f"Credentials not found in your Kedro project config.\n{str(exc)}")

2023-01-08 12:58:06,763 - py.warnings - WARNING - /Users/k9/.pyenv/versions/3.9.11/envs/kedro-on-aws/lib/python3.9/site-packages/kedro/framework/project/__init__.py:330: UserWarning: An error occurred while importing the 'iris.pipeline' module. Nothing defined therein will be returned by 'find_pipelines'.

Traceback (most recent call last):
  File "/Users/k9/.pyenv/versions/3.9.11/envs/kedro-on-aws/lib/python3.9/site-packages/kedro/framework/project/__init__.py", line 327, in find_pipelines
    pipeline_module = importlib.import_module(pipeline_module_name)
  File "/Users/k9/.pyenv/versions/3.9.11/lib/python3.9/importlib/__init__.py", line 127, in import_module
    return _bootstrap._gcd_import(name[level:], package, level)
  File "<frozen importlib._bootstrap>", line 1030, in _gcd_import
  File "<frozen importlib._bootstrap>", line 1007, in _find_and_load
  File "<frozen importlib._bootstrap>", line 986, in _find_and_load_unlocked
  File "<frozen importlib._bootstrap>", line 680, in _load_unlocked
  File "<frozen importlib._bootstrap_external>", line 850, in exec_module
  File "<frozen importlib._bootstrap>", line 228, in _call_with_frames_removed
  File "/Users/k9/kedro-on-aws/src/iris/pipeline.py", line 8, in <module>
    from .nodes import make_predictions, report_accuracy, split_data
ImportError: cannot import name 'make_predictions' from 'iris.nodes' (/Users/k9/kedro-on-aws/src/iris/nodes.py)

  warnings.warn(

2023-01-08 12:58:10,236 - py.warnings - WARNING - /Users/k9/.pyenv/versions/3.9.11/envs/kedro-on-aws/lib/python3.9/site-packages/kedro/framework/context/context.py:339: UserWarning: Credentials not found in your Kedro project config.
No files found in ['/Users/k9/kedro-on-aws/conf/base', '/Users/k9/kedro-on-aws/conf/local'] matching the glob pattern(s): ['credentials*', 'credentials*/**', '**/credentials*']
  warn(f"Credentials not found in your Kedro project config.\n{str(exc)}")

2023-01-08 12:58:10,240 - kedro.ipython - INFO - Kedro project iris
2023-01-08 12:58:10,241 - kedro.ipython - INFO - Defined global variable 'context', 'session', 'catalog' and 'pipelines'
2023-01-08 12:58:10,260 - Comm - ERROR - No such comm target registered: jupyter.widget.control
2023-01-08 12:58:10,263 - Comm - WARNING - No such comm: 09af1770-6d72-4af8-a1b9-b78cf9a06978
2023-01-08 13:02:42,520 - py.warnings - WARNING - /Users/k9/.pyenv/versions/3.9.11/envs/kedro-on-aws/lib/python3.9/site-packages/kedro/framework/context/context.py:339: UserWarning: Credentials not found in your Kedro project config.
No files found in ['/Users/k9/kedro-on-aws/conf/base', '/Users/k9/kedro-on-aws/conf/local'] matching the glob pattern(s): ['credentials*', 'credentials*/**', '**/credentials*']
  warn(f"Credentials not found in your Kedro project config.\n{str(exc)}")

2023-01-08 13:02:42,723 - py.warnings - WARNING - /Users/k9/.pyenv/versions/3.9.11/envs/kedro-on-aws/lib/python3.9/site-packages/kedro/framework/project/__init__.py:330: UserWarning: An error occurred while importing the 'iris.pipeline' module. Nothing defined therein will be returned by 'find_pipelines'.

Traceback (most recent call last):
  File "/Users/k9/.pyenv/versions/3.9.11/envs/kedro-on-aws/lib/python3.9/site-packages/kedro/framework/project/__init__.py", line 327, in find_pipelines
    pipeline_module = importlib.import_module(pipeline_module_name)
  File "/Users/k9/.pyenv/versions/3.9.11/lib/python3.9/importlib/__init__.py", line 127, in import_module
    return _bootstrap._gcd_import(name[level:], package, level)
  File "<frozen importlib._bootstrap>", line 1030, in _gcd_import
  File "<frozen importlib._bootstrap>", line 1007, in _find_and_load
  File "<frozen importlib._bootstrap>", line 986, in _find_and_load_unlocked
  File "<frozen importlib._bootstrap>", line 680, in _load_unlocked
  File "<frozen importlib._bootstrap_external>", line 850, in exec_module
  File "<frozen importlib._bootstrap>", line 228, in _call_with_frames_removed
  File "/Users/k9/kedro-on-aws/src/iris/pipeline.py", line 8, in <module>
    from .nodes import make_predictions, report_accuracy, split_data
ImportError: cannot import name 'make_predictions' from 'iris.nodes' (/Users/k9/kedro-on-aws/src/iris/nodes.py)

  warnings.warn(

2023-01-08 13:02:45,975 - py.warnings - WARNING - /Users/k9/.pyenv/versions/3.9.11/envs/kedro-on-aws/lib/python3.9/site-packages/kedro/framework/context/context.py:339: UserWarning: Credentials not found in your Kedro project config.
No files found in ['/Users/k9/kedro-on-aws/conf/base', '/Users/k9/kedro-on-aws/conf/local'] matching the glob pattern(s): ['credentials*', 'credentials*/**', '**/credentials*']
  warn(f"Credentials not found in your Kedro project config.\n{str(exc)}")

2023-01-08 13:02:45,978 - kedro.ipython - INFO - Kedro project iris
2023-01-08 13:02:45,979 - kedro.ipython - INFO - Defined global variable 'context', 'session', 'catalog' and 'pipelines'
2023-01-08 13:02:49,799 - asyncio - ERROR - Task was destroyed but it is pending!
task: <Task pending name='Task-2' coro=<Kernel.poll_control_queue() running at /Users/k9/.pyenv/versions/3.9.11/envs/kedro-on-aws/lib/python3.9/site-packages/ipykernel/kernelbase.py:284> wait_for=<Future pending cb=[<TaskWakeupMethWrapper object at 0x1045b80a0>()]> cb=[_chain_future.<locals>._call_set_state() at /Users/k9/.pyenv/versions/3.9.11/lib/python3.9/asyncio/futures.py:391]>
2023-01-08 13:02:52,532 - py.warnings - WARNING - /Users/k9/.pyenv/versions/3.9.11/envs/kedro-on-aws/lib/python3.9/site-packages/kedro/framework/context/context.py:339: UserWarning: Credentials not found in your Kedro project config.
No files found in ['/Users/k9/kedro-on-aws/conf/base', '/Users/k9/kedro-on-aws/conf/local'] matching the glob pattern(s): ['credentials*', 'credentials*/**', '**/credentials*']
  warn(f"Credentials not found in your Kedro project config.\n{str(exc)}")

2023-01-08 13:02:52,703 - py.warnings - WARNING - /Users/k9/.pyenv/versions/3.9.11/envs/kedro-on-aws/lib/python3.9/site-packages/kedro/framework/project/__init__.py:330: UserWarning: An error occurred while importing the 'iris.pipeline' module. Nothing defined therein will be returned by 'find_pipelines'.

Traceback (most recent call last):
  File "/Users/k9/.pyenv/versions/3.9.11/envs/kedro-on-aws/lib/python3.9/site-packages/kedro/framework/project/__init__.py", line 327, in find_pipelines
    pipeline_module = importlib.import_module(pipeline_module_name)
  File "/Users/k9/.pyenv/versions/3.9.11/lib/python3.9/importlib/__init__.py", line 127, in import_module
    return _bootstrap._gcd_import(name[level:], package, level)
  File "<frozen importlib._bootstrap>", line 1030, in _gcd_import
  File "<frozen importlib._bootstrap>", line 1007, in _find_and_load
  File "<frozen importlib._bootstrap>", line 986, in _find_and_load_unlocked
  File "<frozen importlib._bootstrap>", line 680, in _load_unlocked
  File "<frozen importlib._bootstrap_external>", line 850, in exec_module
  File "<frozen importlib._bootstrap>", line 228, in _call_with_frames_removed
  File "/Users/k9/kedro-on-aws/src/iris/pipeline.py", line 8, in <module>
    from .nodes import make_predictions, report_accuracy, split_data
ImportError: cannot import name 'make_predictions' from 'iris.nodes' (/Users/k9/kedro-on-aws/src/iris/nodes.py)

  warnings.warn(

2023-01-08 13:02:55,911 - py.warnings - WARNING - /Users/k9/.pyenv/versions/3.9.11/envs/kedro-on-aws/lib/python3.9/site-packages/kedro/framework/context/context.py:339: UserWarning: Credentials not found in your Kedro project config.
No files found in ['/Users/k9/kedro-on-aws/conf/base', '/Users/k9/kedro-on-aws/conf/local'] matching the glob pattern(s): ['credentials*', 'credentials*/**', '**/credentials*']
  warn(f"Credentials not found in your Kedro project config.\n{str(exc)}")

2023-01-08 13:02:55,915 - kedro.ipython - INFO - Kedro project iris
2023-01-08 13:02:55,916 - kedro.ipython - INFO - Defined global variable 'context', 'session', 'catalog' and 'pipelines'
2023-01-08 13:02:55,936 - Comm - ERROR - No such comm target registered: jupyter.widget.control
2023-01-08 13:02:55,938 - Comm - WARNING - No such comm: df4d08df-e041-402e-9c47-1e9f48e907c6
2023-01-08 13:05:54,650 - kedro.io.data_catalog - INFO - Loading data from 'transactions' (AthenaQueryDataSet)...
2023-01-08 13:13:32,469 - asyncio - ERROR - Task was destroyed but it is pending!
task: <Task pending name='Task-2' coro=<Kernel.poll_control_queue() running at /Users/k9/.pyenv/versions/3.9.11/envs/kedro-on-aws/lib/python3.9/site-packages/ipykernel/kernelbase.py:284> wait_for=<Future pending cb=[<TaskWakeupMethWrapper object at 0x10292e820>()]> cb=[_chain_future.<locals>._call_set_state() at /Users/k9/.pyenv/versions/3.9.11/lib/python3.9/asyncio/futures.py:391]>
2023-01-08 13:13:33,544 - py.warnings - WARNING - /Users/k9/.pyenv/versions/3.9.11/envs/kedro-on-aws/lib/python3.9/site-packages/kedro/framework/context/context.py:339: UserWarning: Credentials not found in your Kedro project config.
No files found in ['/Users/k9/kedro-on-aws/conf/base', '/Users/k9/kedro-on-aws/conf/local'] matching the glob pattern(s): ['credentials*', 'credentials*/**', '**/credentials*']
  warn(f"Credentials not found in your Kedro project config.\n{str(exc)}")

2023-01-08 13:13:33,745 - py.warnings - WARNING - /Users/k9/.pyenv/versions/3.9.11/envs/kedro-on-aws/lib/python3.9/site-packages/kedro/framework/project/__init__.py:330: UserWarning: An error occurred while importing the 'iris.pipeline' module. Nothing defined therein will be returned by 'find_pipelines'.

Traceback (most recent call last):
  File "/Users/k9/.pyenv/versions/3.9.11/envs/kedro-on-aws/lib/python3.9/site-packages/kedro/framework/project/__init__.py", line 327, in find_pipelines
    pipeline_module = importlib.import_module(pipeline_module_name)
  File "/Users/k9/.pyenv/versions/3.9.11/lib/python3.9/importlib/__init__.py", line 127, in import_module
    return _bootstrap._gcd_import(name[level:], package, level)
  File "<frozen importlib._bootstrap>", line 1030, in _gcd_import
  File "<frozen importlib._bootstrap>", line 1007, in _find_and_load
  File "<frozen importlib._bootstrap>", line 986, in _find_and_load_unlocked
  File "<frozen importlib._bootstrap>", line 680, in _load_unlocked
  File "<frozen importlib._bootstrap_external>", line 850, in exec_module
  File "<frozen importlib._bootstrap>", line 228, in _call_with_frames_removed
  File "/Users/k9/kedro-on-aws/src/iris/pipeline.py", line 8, in <module>
    from .nodes import make_predictions, report_accuracy, split_data
ImportError: cannot import name 'make_predictions' from 'iris.nodes' (/Users/k9/kedro-on-aws/src/iris/nodes.py)

  warnings.warn(

2023-01-08 13:13:37,327 - py.warnings - WARNING - /Users/k9/.pyenv/versions/3.9.11/envs/kedro-on-aws/lib/python3.9/site-packages/kedro/framework/context/context.py:339: UserWarning: Credentials not found in your Kedro project config.
No files found in ['/Users/k9/kedro-on-aws/conf/base', '/Users/k9/kedro-on-aws/conf/local'] matching the glob pattern(s): ['credentials*', 'credentials*/**', '**/credentials*']
  warn(f"Credentials not found in your Kedro project config.\n{str(exc)}")

2023-01-08 13:13:37,331 - kedro.ipython - INFO - Kedro project iris
2023-01-08 13:13:37,332 - kedro.ipython - INFO - Defined global variable 'context', 'session', 'catalog' and 'pipelines'
2023-01-08 13:21:42,552 - py.warnings - WARNING - /Users/k9/.pyenv/versions/3.9.11/envs/kedro-on-aws/lib/python3.9/site-packages/kedro/framework/context/context.py:339: UserWarning: Credentials not found in your Kedro project config.
No files found in ['/Users/k9/kedro-on-aws/conf/base', '/Users/k9/kedro-on-aws/conf/local'] matching the glob pattern(s): ['credentials*', 'credentials*/**', '**/credentials*']
  warn(f"Credentials not found in your Kedro project config.\n{str(exc)}")

2023-01-08 13:21:42,758 - py.warnings - WARNING - /Users/k9/.pyenv/versions/3.9.11/envs/kedro-on-aws/lib/python3.9/site-packages/kedro/framework/project/__init__.py:330: UserWarning: An error occurred while importing the 'iris.pipeline' module. Nothing defined therein will be returned by 'find_pipelines'.

Traceback (most recent call last):
  File "/Users/k9/.pyenv/versions/3.9.11/envs/kedro-on-aws/lib/python3.9/site-packages/kedro/framework/project/__init__.py", line 327, in find_pipelines
    pipeline_module = importlib.import_module(pipeline_module_name)
  File "/Users/k9/.pyenv/versions/3.9.11/lib/python3.9/importlib/__init__.py", line 127, in import_module
    return _bootstrap._gcd_import(name[level:], package, level)
  File "<frozen importlib._bootstrap>", line 1030, in _gcd_import
  File "<frozen importlib._bootstrap>", line 1007, in _find_and_load
  File "<frozen importlib._bootstrap>", line 986, in _find_and_load_unlocked
  File "<frozen importlib._bootstrap>", line 680, in _load_unlocked
  File "<frozen importlib._bootstrap_external>", line 850, in exec_module
  File "<frozen importlib._bootstrap>", line 228, in _call_with_frames_removed
  File "/Users/k9/kedro-on-aws/src/iris/pipeline.py", line 8, in <module>
    from .nodes import make_predictions, report_accuracy, split_data
ImportError: cannot import name 'make_predictions' from 'iris.nodes' (/Users/k9/kedro-on-aws/src/iris/nodes.py)

  warnings.warn(

2023-01-08 13:21:46,222 - py.warnings - WARNING - /Users/k9/.pyenv/versions/3.9.11/envs/kedro-on-aws/lib/python3.9/site-packages/kedro/framework/context/context.py:339: UserWarning: Credentials not found in your Kedro project config.
No files found in ['/Users/k9/kedro-on-aws/conf/base', '/Users/k9/kedro-on-aws/conf/local'] matching the glob pattern(s): ['credentials*', 'credentials*/**', '**/credentials*']
  warn(f"Credentials not found in your Kedro project config.\n{str(exc)}")

2023-01-08 13:21:46,226 - kedro.ipython - INFO - Kedro project iris
2023-01-08 13:21:46,227 - kedro.ipython - INFO - Defined global variable 'context', 'session', 'catalog' and 'pipelines'
2023-01-08 13:21:47,681 - py.warnings - WARNING - /Users/k9/.pyenv/versions/3.9.11/envs/kedro-on-aws/lib/python3.9/site-packages/kedro/framework/context/context.py:339: UserWarning: Credentials not found in your Kedro project config.
No files found in ['/Users/k9/kedro-on-aws/conf/base', '/Users/k9/kedro-on-aws/conf/local'] matching the glob pattern(s): ['credentials*', 'credentials*/**', '**/credentials*']
  warn(f"Credentials not found in your Kedro project config.\n{str(exc)}")

2023-01-08 13:21:47,855 - py.warnings - WARNING - /Users/k9/.pyenv/versions/3.9.11/envs/kedro-on-aws/lib/python3.9/site-packages/kedro/framework/project/__init__.py:330: UserWarning: An error occurred while importing the 'iris.pipeline' module. Nothing defined therein will be returned by 'find_pipelines'.

Traceback (most recent call last):
  File "/Users/k9/.pyenv/versions/3.9.11/envs/kedro-on-aws/lib/python3.9/site-packages/kedro/framework/project/__init__.py", line 327, in find_pipelines
    pipeline_module = importlib.import_module(pipeline_module_name)
  File "/Users/k9/.pyenv/versions/3.9.11/lib/python3.9/importlib/__init__.py", line 127, in import_module
    return _bootstrap._gcd_import(name[level:], package, level)
  File "<frozen importlib._bootstrap>", line 1030, in _gcd_import
  File "<frozen importlib._bootstrap>", line 1007, in _find_and_load
  File "<frozen importlib._bootstrap>", line 986, in _find_and_load_unlocked
  File "<frozen importlib._bootstrap>", line 680, in _load_unlocked
  File "<frozen importlib._bootstrap_external>", line 850, in exec_module
  File "<frozen importlib._bootstrap>", line 228, in _call_with_frames_removed
  File "/Users/k9/kedro-on-aws/src/iris/pipeline.py", line 8, in <module>
    from .nodes import make_predictions, report_accuracy, split_data
ImportError: cannot import name 'make_predictions' from 'iris.nodes' (/Users/k9/kedro-on-aws/src/iris/nodes.py)

  warnings.warn(

2023-01-08 13:21:50,900 - py.warnings - WARNING - /Users/k9/.pyenv/versions/3.9.11/envs/kedro-on-aws/lib/python3.9/site-packages/kedro/framework/context/context.py:339: UserWarning: Credentials not found in your Kedro project config.
No files found in ['/Users/k9/kedro-on-aws/conf/base', '/Users/k9/kedro-on-aws/conf/local'] matching the glob pattern(s): ['credentials*', 'credentials*/**', '**/credentials*']
  warn(f"Credentials not found in your Kedro project config.\n{str(exc)}")

2023-01-08 13:21:50,904 - kedro.ipython - INFO - Kedro project iris
2023-01-08 13:21:50,905 - kedro.ipython - INFO - Defined global variable 'context', 'session', 'catalog' and 'pipelines'
2023-01-08 13:27:14,861 - kedro.io.data_catalog - INFO - Loading data from 'transactions' (AthenaQueryDataSet)...
2023-01-08 13:31:35,203 - asyncio - ERROR - Task was destroyed but it is pending!
task: <Task pending name='Task-2' coro=<Kernel.poll_control_queue() running at /Users/k9/.pyenv/versions/3.9.11/envs/kedro-on-aws/lib/python3.9/site-packages/ipykernel/kernelbase.py:284> wait_for=<Future pending cb=[<TaskWakeupMethWrapper object at 0x107246f70>()]> cb=[_chain_future.<locals>._call_set_state() at /Users/k9/.pyenv/versions/3.9.11/lib/python3.9/asyncio/futures.py:391]>
2023-01-08 13:31:36,265 - py.warnings - WARNING - /Users/k9/.pyenv/versions/3.9.11/envs/kedro-on-aws/lib/python3.9/site-packages/kedro/framework/context/context.py:339: UserWarning: Credentials not found in your Kedro project config.
No files found in ['/Users/k9/kedro-on-aws/conf/base', '/Users/k9/kedro-on-aws/conf/local'] matching the glob pattern(s): ['credentials*', 'credentials*/**', '**/credentials*']
  warn(f"Credentials not found in your Kedro project config.\n{str(exc)}")

2023-01-08 13:31:36,475 - py.warnings - WARNING - /Users/k9/.pyenv/versions/3.9.11/envs/kedro-on-aws/lib/python3.9/site-packages/kedro/framework/project/__init__.py:330: UserWarning: An error occurred while importing the 'iris.pipeline' module. Nothing defined therein will be returned by 'find_pipelines'.

Traceback (most recent call last):
  File "/Users/k9/.pyenv/versions/3.9.11/envs/kedro-on-aws/lib/python3.9/site-packages/kedro/framework/project/__init__.py", line 327, in find_pipelines
    pipeline_module = importlib.import_module(pipeline_module_name)
  File "/Users/k9/.pyenv/versions/3.9.11/lib/python3.9/importlib/__init__.py", line 127, in import_module
    return _bootstrap._gcd_import(name[level:], package, level)
  File "<frozen importlib._bootstrap>", line 1030, in _gcd_import
  File "<frozen importlib._bootstrap>", line 1007, in _find_and_load
  File "<frozen importlib._bootstrap>", line 986, in _find_and_load_unlocked
  File "<frozen importlib._bootstrap>", line 680, in _load_unlocked
  File "<frozen importlib._bootstrap_external>", line 850, in exec_module
  File "<frozen importlib._bootstrap>", line 228, in _call_with_frames_removed
  File "/Users/k9/kedro-on-aws/src/iris/pipeline.py", line 8, in <module>
    from .nodes import make_predictions, report_accuracy, split_data
ImportError: cannot import name 'make_predictions' from 'iris.nodes' (/Users/k9/kedro-on-aws/src/iris/nodes.py)

  warnings.warn(

2023-01-08 13:31:39,948 - py.warnings - WARNING - /Users/k9/.pyenv/versions/3.9.11/envs/kedro-on-aws/lib/python3.9/site-packages/kedro/framework/context/context.py:339: UserWarning: Credentials not found in your Kedro project config.
No files found in ['/Users/k9/kedro-on-aws/conf/base', '/Users/k9/kedro-on-aws/conf/local'] matching the glob pattern(s): ['credentials*', 'credentials*/**', '**/credentials*']
  warn(f"Credentials not found in your Kedro project config.\n{str(exc)}")

2023-01-08 13:31:39,952 - kedro.ipython - INFO - Kedro project iris
2023-01-08 13:31:39,953 - kedro.ipython - INFO - Defined global variable 'context', 'session', 'catalog' and 'pipelines'
2023-01-08 13:32:13,667 - kedro.io.data_catalog - INFO - Loading data from 'transactions' (AthenaQueryDataSet)...
2023-01-08 13:40:14,946 - asyncio - ERROR - Task was destroyed but it is pending!
task: <Task pending name='Task-2' coro=<Kernel.poll_control_queue() running at /Users/k9/.pyenv/versions/3.9.11/envs/kedro-on-aws/lib/python3.9/site-packages/ipykernel/kernelbase.py:284> wait_for=<Future pending cb=[<TaskWakeupMethWrapper object at 0x107d126a0>()]> cb=[_chain_future.<locals>._call_set_state() at /Users/k9/.pyenv/versions/3.9.11/lib/python3.9/asyncio/futures.py:391]>
2023-01-08 13:40:15,982 - py.warnings - WARNING - /Users/k9/.pyenv/versions/3.9.11/envs/kedro-on-aws/lib/python3.9/site-packages/kedro/framework/context/context.py:339: UserWarning: Credentials not found in your Kedro project config.
No files found in ['/Users/k9/kedro-on-aws/conf/base', '/Users/k9/kedro-on-aws/conf/local'] matching the glob pattern(s): ['credentials*', 'credentials*/**', '**/credentials*']
  warn(f"Credentials not found in your Kedro project config.\n{str(exc)}")

2023-01-08 13:40:16,187 - py.warnings - WARNING - /Users/k9/.pyenv/versions/3.9.11/envs/kedro-on-aws/lib/python3.9/site-packages/kedro/framework/project/__init__.py:330: UserWarning: An error occurred while importing the 'iris.pipeline' module. Nothing defined therein will be returned by 'find_pipelines'.

Traceback (most recent call last):
  File "/Users/k9/.pyenv/versions/3.9.11/envs/kedro-on-aws/lib/python3.9/site-packages/kedro/framework/project/__init__.py", line 327, in find_pipelines
    pipeline_module = importlib.import_module(pipeline_module_name)
  File "/Users/k9/.pyenv/versions/3.9.11/lib/python3.9/importlib/__init__.py", line 127, in import_module
    return _bootstrap._gcd_import(name[level:], package, level)
  File "<frozen importlib._bootstrap>", line 1030, in _gcd_import
  File "<frozen importlib._bootstrap>", line 1007, in _find_and_load
  File "<frozen importlib._bootstrap>", line 986, in _find_and_load_unlocked
  File "<frozen importlib._bootstrap>", line 680, in _load_unlocked
  File "<frozen importlib._bootstrap_external>", line 850, in exec_module
  File "<frozen importlib._bootstrap>", line 228, in _call_with_frames_removed
  File "/Users/k9/kedro-on-aws/src/iris/pipeline.py", line 8, in <module>
    from .nodes import make_predictions, report_accuracy, split_data
ImportError: cannot import name 'make_predictions' from 'iris.nodes' (/Users/k9/kedro-on-aws/src/iris/nodes.py)

  warnings.warn(

2023-01-08 13:40:19,657 - py.warnings - WARNING - /Users/k9/.pyenv/versions/3.9.11/envs/kedro-on-aws/lib/python3.9/site-packages/kedro/framework/context/context.py:339: UserWarning: Credentials not found in your Kedro project config.
No files found in ['/Users/k9/kedro-on-aws/conf/base', '/Users/k9/kedro-on-aws/conf/local'] matching the glob pattern(s): ['credentials*', 'credentials*/**', '**/credentials*']
  warn(f"Credentials not found in your Kedro project config.\n{str(exc)}")

2023-01-08 13:40:19,661 - kedro.ipython - INFO - Kedro project iris
2023-01-08 13:40:19,661 - kedro.ipython - INFO - Defined global variable 'context', 'session', 'catalog' and 'pipelines'
2023-01-08 13:40:23,738 - kedro.io.data_catalog - INFO - Loading data from 'transactions' (AthenaQueryDataSet)...
2023-01-08 13:42:43,624 - asyncio - ERROR - Task was destroyed but it is pending!
task: <Task pending name='Task-2' coro=<Kernel.poll_control_queue() running at /Users/k9/.pyenv/versions/3.9.11/envs/kedro-on-aws/lib/python3.9/site-packages/ipykernel/kernelbase.py:284> wait_for=<Future pending cb=[<TaskWakeupMethWrapper object at 0x12420cd30>()]> cb=[_chain_future.<locals>._call_set_state() at /Users/k9/.pyenv/versions/3.9.11/lib/python3.9/asyncio/futures.py:391]>
2023-01-08 13:42:44,520 - py.warnings - WARNING - /Users/k9/.pyenv/versions/3.9.11/envs/kedro-on-aws/lib/python3.9/site-packages/kedro/framework/context/context.py:339: UserWarning: Credentials not found in your Kedro project config.
No files found in ['/Users/k9/kedro-on-aws/conf/base', '/Users/k9/kedro-on-aws/conf/local'] matching the glob pattern(s): ['credentials*', 'credentials*/**', '**/credentials*']
  warn(f"Credentials not found in your Kedro project config.\n{str(exc)}")

2023-01-08 13:42:44,694 - py.warnings - WARNING - /Users/k9/.pyenv/versions/3.9.11/envs/kedro-on-aws/lib/python3.9/site-packages/kedro/framework/project/__init__.py:330: UserWarning: An error occurred while importing the 'iris.pipeline' module. Nothing defined therein will be returned by 'find_pipelines'.

Traceback (most recent call last):
  File "/Users/k9/.pyenv/versions/3.9.11/envs/kedro-on-aws/lib/python3.9/site-packages/kedro/framework/project/__init__.py", line 327, in find_pipelines
    pipeline_module = importlib.import_module(pipeline_module_name)
  File "/Users/k9/.pyenv/versions/3.9.11/lib/python3.9/importlib/__init__.py", line 127, in import_module
    return _bootstrap._gcd_import(name[level:], package, level)
  File "<frozen importlib._bootstrap>", line 1030, in _gcd_import
  File "<frozen importlib._bootstrap>", line 1007, in _find_and_load
  File "<frozen importlib._bootstrap>", line 986, in _find_and_load_unlocked
  File "<frozen importlib._bootstrap>", line 680, in _load_unlocked
  File "<frozen importlib._bootstrap_external>", line 850, in exec_module
  File "<frozen importlib._bootstrap>", line 228, in _call_with_frames_removed
  File "/Users/k9/kedro-on-aws/src/iris/pipeline.py", line 8, in <module>
    from .nodes import make_predictions, report_accuracy, split_data
ImportError: cannot import name 'make_predictions' from 'iris.nodes' (/Users/k9/kedro-on-aws/src/iris/nodes.py)

  warnings.warn(

2023-01-08 13:42:47,898 - py.warnings - WARNING - /Users/k9/.pyenv/versions/3.9.11/envs/kedro-on-aws/lib/python3.9/site-packages/kedro/framework/context/context.py:339: UserWarning: Credentials not found in your Kedro project config.
No files found in ['/Users/k9/kedro-on-aws/conf/base', '/Users/k9/kedro-on-aws/conf/local'] matching the glob pattern(s): ['credentials*', 'credentials*/**', '**/credentials*']
  warn(f"Credentials not found in your Kedro project config.\n{str(exc)}")

2023-01-08 13:42:47,902 - kedro.ipython - INFO - Kedro project iris
2023-01-08 13:42:47,903 - kedro.ipython - INFO - Defined global variable 'context', 'session', 'catalog' and 'pipelines'
2023-01-08 13:42:50,211 - kedro.io.data_catalog - INFO - Loading data from 'transactions' (AthenaQueryDataSet)...
2023-01-08 13:44:57,503 - asyncio - ERROR - Task was destroyed but it is pending!
task: <Task pending name='Task-2' coro=<Kernel.poll_control_queue() running at /Users/k9/.pyenv/versions/3.9.11/envs/kedro-on-aws/lib/python3.9/site-packages/ipykernel/kernelbase.py:284> wait_for=<Future pending cb=[<TaskWakeupMethWrapper object at 0x10604e6a0>()]> cb=[_chain_future.<locals>._call_set_state() at /Users/k9/.pyenv/versions/3.9.11/lib/python3.9/asyncio/futures.py:391]>
2023-01-08 13:44:58,386 - py.warnings - WARNING - /Users/k9/.pyenv/versions/3.9.11/envs/kedro-on-aws/lib/python3.9/site-packages/kedro/framework/context/context.py:339: UserWarning: Credentials not found in your Kedro project config.
No files found in ['/Users/k9/kedro-on-aws/conf/base', '/Users/k9/kedro-on-aws/conf/local'] matching the glob pattern(s): ('credentials*', 'credentials*/**', '**/credentials*')
  warn(f"Credentials not found in your Kedro project config.\n{str(exc)}")

2023-01-08 13:44:58,569 - py.warnings - WARNING - /Users/k9/.pyenv/versions/3.9.11/envs/kedro-on-aws/lib/python3.9/site-packages/kedro/framework/project/__init__.py:330: UserWarning: An error occurred while importing the 'iris.pipeline' module. Nothing defined therein will be returned by 'find_pipelines'.

Traceback (most recent call last):
  File "/Users/k9/.pyenv/versions/3.9.11/envs/kedro-on-aws/lib/python3.9/site-packages/kedro/framework/project/__init__.py", line 327, in find_pipelines
    pipeline_module = importlib.import_module(pipeline_module_name)
  File "/Users/k9/.pyenv/versions/3.9.11/lib/python3.9/importlib/__init__.py", line 127, in import_module
    return _bootstrap._gcd_import(name[level:], package, level)
  File "<frozen importlib._bootstrap>", line 1030, in _gcd_import
  File "<frozen importlib._bootstrap>", line 1007, in _find_and_load
  File "<frozen importlib._bootstrap>", line 986, in _find_and_load_unlocked
  File "<frozen importlib._bootstrap>", line 680, in _load_unlocked
  File "<frozen importlib._bootstrap_external>", line 850, in exec_module
  File "<frozen importlib._bootstrap>", line 228, in _call_with_frames_removed
  File "/Users/k9/kedro-on-aws/src/iris/pipeline.py", line 8, in <module>
    from .nodes import make_predictions, report_accuracy, split_data
ImportError: cannot import name 'make_predictions' from 'iris.nodes' (/Users/k9/kedro-on-aws/src/iris/nodes.py)

  warnings.warn(

2023-01-08 13:45:01,840 - py.warnings - WARNING - /Users/k9/.pyenv/versions/3.9.11/envs/kedro-on-aws/lib/python3.9/site-packages/kedro/framework/context/context.py:339: UserWarning: Credentials not found in your Kedro project config.
No files found in ['/Users/k9/kedro-on-aws/conf/base', '/Users/k9/kedro-on-aws/conf/local'] matching the glob pattern(s): ('credentials*', 'credentials*/**', '**/credentials*')
  warn(f"Credentials not found in your Kedro project config.\n{str(exc)}")

2023-01-08 13:45:01,844 - kedro.ipython - INFO - Kedro project iris
2023-01-08 13:45:01,845 - kedro.ipython - INFO - Defined global variable 'context', 'session', 'catalog' and 'pipelines'
2023-01-08 13:45:19,607 - kedro.io.data_catalog - INFO - Loading data from 'transactions' (AthenaQueryDataSet)...
2023-01-08 13:48:25,816 - asyncio - ERROR - Task was destroyed but it is pending!
task: <Task pending name='Task-2' coro=<Kernel.poll_control_queue() running at /Users/k9/.pyenv/versions/3.9.11/envs/kedro-on-aws/lib/python3.9/site-packages/ipykernel/kernelbase.py:284> wait_for=<Future pending cb=[<TaskWakeupMethWrapper object at 0x105955f70>()]> cb=[_chain_future.<locals>._call_set_state() at /Users/k9/.pyenv/versions/3.9.11/lib/python3.9/asyncio/futures.py:391]>
2023-01-08 13:48:26,710 - py.warnings - WARNING - /Users/k9/.pyenv/versions/3.9.11/envs/kedro-on-aws/lib/python3.9/site-packages/kedro/framework/context/context.py:339: UserWarning: Credentials not found in your Kedro project config.
No files found in ['/Users/k9/kedro-on-aws/conf/base', '/Users/k9/kedro-on-aws/conf/local'] matching the glob pattern(s): ('credentials*', 'credentials*/**', '**/credentials*')
  warn(f"Credentials not found in your Kedro project config.\n{str(exc)}")

2023-01-08 13:48:26,881 - py.warnings - WARNING - /Users/k9/.pyenv/versions/3.9.11/envs/kedro-on-aws/lib/python3.9/site-packages/kedro/framework/project/__init__.py:330: UserWarning: An error occurred while importing the 'iris.pipeline' module. Nothing defined therein will be returned by 'find_pipelines'.

Traceback (most recent call last):
  File "/Users/k9/.pyenv/versions/3.9.11/envs/kedro-on-aws/lib/python3.9/site-packages/kedro/framework/project/__init__.py", line 327, in find_pipelines
    pipeline_module = importlib.import_module(pipeline_module_name)
  File "/Users/k9/.pyenv/versions/3.9.11/lib/python3.9/importlib/__init__.py", line 127, in import_module
    return _bootstrap._gcd_import(name[level:], package, level)
  File "<frozen importlib._bootstrap>", line 1030, in _gcd_import
  File "<frozen importlib._bootstrap>", line 1007, in _find_and_load
  File "<frozen importlib._bootstrap>", line 986, in _find_and_load_unlocked
  File "<frozen importlib._bootstrap>", line 680, in _load_unlocked
  File "<frozen importlib._bootstrap_external>", line 850, in exec_module
  File "<frozen importlib._bootstrap>", line 228, in _call_with_frames_removed
  File "/Users/k9/kedro-on-aws/src/iris/pipeline.py", line 8, in <module>
    from .nodes import make_predictions, report_accuracy, split_data
ImportError: cannot import name 'make_predictions' from 'iris.nodes' (/Users/k9/kedro-on-aws/src/iris/nodes.py)

  warnings.warn(

2023-01-08 13:48:30,333 - py.warnings - WARNING - /Users/k9/.pyenv/versions/3.9.11/envs/kedro-on-aws/lib/python3.9/site-packages/kedro/framework/context/context.py:339: UserWarning: Credentials not found in your Kedro project config.
No files found in ['/Users/k9/kedro-on-aws/conf/base', '/Users/k9/kedro-on-aws/conf/local'] matching the glob pattern(s): ('credentials*', 'credentials*/**', '**/credentials*')
  warn(f"Credentials not found in your Kedro project config.\n{str(exc)}")

2023-01-08 13:48:30,337 - kedro.ipython - INFO - Kedro project iris
2023-01-08 13:48:30,338 - kedro.ipython - INFO - Defined global variable 'context', 'session', 'catalog' and 'pipelines'
2023-01-08 13:48:30,574 - kedro.io.data_catalog - INFO - Loading data from 'transactions' (AthenaQueryDataSet)...
2023-01-08 13:49:19,907 - asyncio - ERROR - Task was destroyed but it is pending!
task: <Task pending name='Task-2' coro=<Kernel.poll_control_queue() running at /Users/k9/.pyenv/versions/3.9.11/envs/kedro-on-aws/lib/python3.9/site-packages/ipykernel/kernelbase.py:284> wait_for=<Future pending cb=[<TaskWakeupMethWrapper object at 0x104d3b820>()]> cb=[_chain_future.<locals>._call_set_state() at /Users/k9/.pyenv/versions/3.9.11/lib/python3.9/asyncio/futures.py:391]>
2023-01-08 13:49:20,826 - py.warnings - WARNING - /Users/k9/.pyenv/versions/3.9.11/envs/kedro-on-aws/lib/python3.9/site-packages/kedro/framework/context/context.py:339: UserWarning: Credentials not found in your Kedro project config.
No files found in ['/Users/k9/kedro-on-aws/conf/base', '/Users/k9/kedro-on-aws/conf/local'] matching the glob pattern(s): ('credentials*', 'credentials*/**', '**/credentials*')
  warn(f"Credentials not found in your Kedro project config.\n{str(exc)}")

2023-01-08 13:49:21,000 - py.warnings - WARNING - /Users/k9/.pyenv/versions/3.9.11/envs/kedro-on-aws/lib/python3.9/site-packages/kedro/framework/project/__init__.py:330: UserWarning: An error occurred while importing the 'iris.pipeline' module. Nothing defined therein will be returned by 'find_pipelines'.

Traceback (most recent call last):
  File "/Users/k9/.pyenv/versions/3.9.11/envs/kedro-on-aws/lib/python3.9/site-packages/kedro/framework/project/__init__.py", line 327, in find_pipelines
    pipeline_module = importlib.import_module(pipeline_module_name)
  File "/Users/k9/.pyenv/versions/3.9.11/lib/python3.9/importlib/__init__.py", line 127, in import_module
    return _bootstrap._gcd_import(name[level:], package, level)
  File "<frozen importlib._bootstrap>", line 1030, in _gcd_import
  File "<frozen importlib._bootstrap>", line 1007, in _find_and_load
  File "<frozen importlib._bootstrap>", line 986, in _find_and_load_unlocked
  File "<frozen importlib._bootstrap>", line 680, in _load_unlocked
  File "<frozen importlib._bootstrap_external>", line 850, in exec_module
  File "<frozen importlib._bootstrap>", line 228, in _call_with_frames_removed
  File "/Users/k9/kedro-on-aws/src/iris/pipeline.py", line 8, in <module>
    from .nodes import make_predictions, report_accuracy, split_data
ImportError: cannot import name 'make_predictions' from 'iris.nodes' (/Users/k9/kedro-on-aws/src/iris/nodes.py)

  warnings.warn(

2023-01-08 13:49:24,326 - py.warnings - WARNING - /Users/k9/.pyenv/versions/3.9.11/envs/kedro-on-aws/lib/python3.9/site-packages/kedro/framework/context/context.py:339: UserWarning: Credentials not found in your Kedro project config.
No files found in ['/Users/k9/kedro-on-aws/conf/base', '/Users/k9/kedro-on-aws/conf/local'] matching the glob pattern(s): ('credentials*', 'credentials*/**', '**/credentials*')
  warn(f"Credentials not found in your Kedro project config.\n{str(exc)}")

2023-01-08 13:49:24,330 - kedro.ipython - INFO - Kedro project iris
2023-01-08 13:49:24,331 - kedro.ipython - INFO - Defined global variable 'context', 'session', 'catalog' and 'pipelines'
2023-01-08 13:49:27,691 - kedro.io.data_catalog - INFO - Loading data from 'transactions' (AthenaQueryDataSet)...
2023-01-08 14:07:54,838 - asyncio - ERROR - Task was destroyed but it is pending!
task: <Task pending name='Task-2' coro=<Kernel.poll_control_queue() running at /Users/k9/.pyenv/versions/3.9.11/envs/kedro-on-aws/lib/python3.9/site-packages/ipykernel/kernelbase.py:284> wait_for=<Future pending cb=[<TaskWakeupMethWrapper object at 0x109891c40>()]> cb=[_chain_future.<locals>._call_set_state() at /Users/k9/.pyenv/versions/3.9.11/lib/python3.9/asyncio/futures.py:391]>
2023-01-08 14:07:55,972 - py.warnings - WARNING - /Users/k9/.pyenv/versions/3.9.11/envs/kedro-on-aws/lib/python3.9/site-packages/kedro/framework/context/context.py:339: UserWarning: Credentials not found in your Kedro project config.
No files found in ['/Users/k9/kedro-on-aws/conf/base', '/Users/k9/kedro-on-aws/conf/local'] matching the glob pattern(s): ('credentials*', 'credentials*/**', '**/credentials*')
  warn(f"Credentials not found in your Kedro project config.\n{str(exc)}")

2023-01-08 14:07:56,186 - py.warnings - WARNING - /Users/k9/.pyenv/versions/3.9.11/envs/kedro-on-aws/lib/python3.9/site-packages/kedro/framework/project/__init__.py:330: UserWarning: An error occurred while importing the 'iris.pipeline' module. Nothing defined therein will be returned by 'find_pipelines'.

Traceback (most recent call last):
  File "/Users/k9/.pyenv/versions/3.9.11/envs/kedro-on-aws/lib/python3.9/site-packages/kedro/framework/project/__init__.py", line 327, in find_pipelines
    pipeline_module = importlib.import_module(pipeline_module_name)
  File "/Users/k9/.pyenv/versions/3.9.11/lib/python3.9/importlib/__init__.py", line 127, in import_module
    return _bootstrap._gcd_import(name[level:], package, level)
  File "<frozen importlib._bootstrap>", line 1030, in _gcd_import
  File "<frozen importlib._bootstrap>", line 1007, in _find_and_load
  File "<frozen importlib._bootstrap>", line 986, in _find_and_load_unlocked
  File "<frozen importlib._bootstrap>", line 680, in _load_unlocked
  File "<frozen importlib._bootstrap_external>", line 850, in exec_module
  File "<frozen importlib._bootstrap>", line 228, in _call_with_frames_removed
  File "/Users/k9/kedro-on-aws/src/iris/pipeline.py", line 8, in <module>
    from .nodes import make_predictions, report_accuracy, split_data
ImportError: cannot import name 'make_predictions' from 'iris.nodes' (/Users/k9/kedro-on-aws/src/iris/nodes.py)

  warnings.warn(

2023-01-08 14:07:59,689 - py.warnings - WARNING - /Users/k9/.pyenv/versions/3.9.11/envs/kedro-on-aws/lib/python3.9/site-packages/kedro/framework/context/context.py:339: UserWarning: Credentials not found in your Kedro project config.
No files found in ['/Users/k9/kedro-on-aws/conf/base', '/Users/k9/kedro-on-aws/conf/local'] matching the glob pattern(s): ('credentials*', 'credentials*/**', '**/credentials*')
  warn(f"Credentials not found in your Kedro project config.\n{str(exc)}")

2023-01-08 14:07:59,692 - kedro.ipython - INFO - Kedro project iris
2023-01-08 14:07:59,693 - kedro.ipython - INFO - Defined global variable 'context', 'session', 'catalog' and 'pipelines'
2023-01-08 14:08:01,707 - kedro.io.data_catalog - INFO - Loading data from 'transactions' (AthenaQueryDataSet)...
2023-01-08 14:23:05,031 - asyncio - ERROR - Task was destroyed but it is pending!
task: <Task pending name='Task-1' coro=<Kernel.poll_control_queue() running at /Users/k9/.pyenv/versions/3.9.11/envs/kedro-on-aws/lib/python3.9/site-packages/ipykernel/kernelbase.py:284> wait_for=<Future pending cb=[<TaskWakeupMethWrapper object at 0x107aa1f40>()]> cb=[_chain_future.<locals>._call_set_state() at /Users/k9/.pyenv/versions/3.9.11/lib/python3.9/asyncio/futures.py:391]>
2023-01-08 14:23:05,928 - py.warnings - WARNING - /Users/k9/.pyenv/versions/3.9.11/envs/kedro-on-aws/lib/python3.9/site-packages/kedro/framework/context/context.py:339: UserWarning: Credentials not found in your Kedro project config.
No files found in ['/Users/k9/kedro-on-aws/conf/base', '/Users/k9/kedro-on-aws/conf/local'] matching the glob pattern(s): ('credentials*', 'credentials*/**', '**/credentials*')
  warn(f"Credentials not found in your Kedro project config.\n{str(exc)}")

2023-01-08 14:23:06,102 - py.warnings - WARNING - /Users/k9/.pyenv/versions/3.9.11/envs/kedro-on-aws/lib/python3.9/site-packages/kedro/framework/project/__init__.py:330: UserWarning: An error occurred while importing the 'iris.pipeline' module. Nothing defined therein will be returned by 'find_pipelines'.

Traceback (most recent call last):
  File "/Users/k9/.pyenv/versions/3.9.11/envs/kedro-on-aws/lib/python3.9/site-packages/kedro/framework/project/__init__.py", line 327, in find_pipelines
    pipeline_module = importlib.import_module(pipeline_module_name)
  File "/Users/k9/.pyenv/versions/3.9.11/lib/python3.9/importlib/__init__.py", line 127, in import_module
    return _bootstrap._gcd_import(name[level:], package, level)
  File "<frozen importlib._bootstrap>", line 1030, in _gcd_import
  File "<frozen importlib._bootstrap>", line 1007, in _find_and_load
  File "<frozen importlib._bootstrap>", line 986, in _find_and_load_unlocked
  File "<frozen importlib._bootstrap>", line 680, in _load_unlocked
  File "<frozen importlib._bootstrap_external>", line 850, in exec_module
  File "<frozen importlib._bootstrap>", line 228, in _call_with_frames_removed
  File "/Users/k9/kedro-on-aws/src/iris/pipeline.py", line 8, in <module>
    from .nodes import make_predictions, report_accuracy, split_data
ImportError: cannot import name 'make_predictions' from 'iris.nodes' (/Users/k9/kedro-on-aws/src/iris/nodes.py)

  warnings.warn(

2023-01-08 14:23:09,212 - py.warnings - WARNING - /Users/k9/.pyenv/versions/3.9.11/envs/kedro-on-aws/lib/python3.9/site-packages/kedro/framework/context/context.py:339: UserWarning: Credentials not found in your Kedro project config.
No files found in ['/Users/k9/kedro-on-aws/conf/base', '/Users/k9/kedro-on-aws/conf/local'] matching the glob pattern(s): ('credentials*', 'credentials*/**', '**/credentials*')
  warn(f"Credentials not found in your Kedro project config.\n{str(exc)}")

2023-01-08 14:23:09,216 - kedro.ipython - INFO - Kedro project iris
2023-01-08 14:23:09,217 - kedro.ipython - INFO - Defined global variable 'context', 'session', 'catalog' and 'pipelines'
2023-01-08 14:23:25,274 - kedro.io.data_catalog - INFO - Loading data from 'transactions' (AthenaQueryDataSet)...
2023-01-08 14:23:30,814 - iris.extras.datasets.athena_dataset - INFO - Athena query output saved to: s3://k9-eth/athena-output/tables/944214e7-e526-47a5-b08e-d07e6c7f53d8
2023-01-08 14:32:24,010 - asyncio - ERROR - Task was destroyed but it is pending!
task: <Task pending name='Task-2' coro=<Kernel.poll_control_queue() running at /Users/k9/.pyenv/versions/3.9.11/envs/kedro-on-aws/lib/python3.9/site-packages/ipykernel/kernelbase.py:284> wait_for=<Future pending cb=[<TaskWakeupMethWrapper object at 0x107dd6f70>()]> cb=[_chain_future.<locals>._call_set_state() at /Users/k9/.pyenv/versions/3.9.11/lib/python3.9/asyncio/futures.py:391]>
2023-01-08 14:32:24,909 - py.warnings - WARNING - /Users/k9/.pyenv/versions/3.9.11/envs/kedro-on-aws/lib/python3.9/site-packages/kedro/framework/context/context.py:339: UserWarning: Credentials not found in your Kedro project config.
No files found in ['/Users/k9/kedro-on-aws/conf/base', '/Users/k9/kedro-on-aws/conf/local'] matching the glob pattern(s): ('credentials*', 'credentials*/**', '**/credentials*')
  warn(f"Credentials not found in your Kedro project config.\n{str(exc)}")

2023-01-08 14:32:25,080 - py.warnings - WARNING - /Users/k9/.pyenv/versions/3.9.11/envs/kedro-on-aws/lib/python3.9/site-packages/kedro/framework/project/__init__.py:330: UserWarning: An error occurred while importing the 'iris.pipeline' module. Nothing defined therein will be returned by 'find_pipelines'.

Traceback (most recent call last):
  File "/Users/k9/.pyenv/versions/3.9.11/envs/kedro-on-aws/lib/python3.9/site-packages/kedro/framework/project/__init__.py", line 327, in find_pipelines
    pipeline_module = importlib.import_module(pipeline_module_name)
  File "/Users/k9/.pyenv/versions/3.9.11/lib/python3.9/importlib/__init__.py", line 127, in import_module
    return _bootstrap._gcd_import(name[level:], package, level)
  File "<frozen importlib._bootstrap>", line 1030, in _gcd_import
  File "<frozen importlib._bootstrap>", line 1007, in _find_and_load
  File "<frozen importlib._bootstrap>", line 986, in _find_and_load_unlocked
  File "<frozen importlib._bootstrap>", line 680, in _load_unlocked
  File "<frozen importlib._bootstrap_external>", line 850, in exec_module
  File "<frozen importlib._bootstrap>", line 228, in _call_with_frames_removed
  File "/Users/k9/kedro-on-aws/src/iris/pipeline.py", line 8, in <module>
    from .nodes import make_predictions, report_accuracy, split_data
ImportError: cannot import name 'make_predictions' from 'iris.nodes' (/Users/k9/kedro-on-aws/src/iris/nodes.py)

  warnings.warn(

2023-01-08 14:32:28,258 - py.warnings - WARNING - /Users/k9/.pyenv/versions/3.9.11/envs/kedro-on-aws/lib/python3.9/site-packages/kedro/framework/context/context.py:339: UserWarning: Credentials not found in your Kedro project config.
No files found in ['/Users/k9/kedro-on-aws/conf/base', '/Users/k9/kedro-on-aws/conf/local'] matching the glob pattern(s): ('credentials*', 'credentials*/**', '**/credentials*')
  warn(f"Credentials not found in your Kedro project config.\n{str(exc)}")

2023-01-08 14:32:28,262 - kedro.ipython - INFO - Kedro project iris
2023-01-08 14:32:28,263 - kedro.ipython - INFO - Defined global variable 'context', 'session', 'catalog' and 'pipelines'
2023-01-08 14:32:37,855 - kedro.io.data_catalog - INFO - Loading data from 'transactions' (AthenaQueryDataSet)...
2023-01-08 14:36:12,387 - asyncio - ERROR - Task was destroyed but it is pending!
task: <Task pending name='Task-2' coro=<Kernel.poll_control_queue() running at /Users/k9/.pyenv/versions/3.9.11/envs/kedro-on-aws/lib/python3.9/site-packages/ipykernel/kernelbase.py:284> wait_for=<Future pending cb=[<TaskWakeupMethWrapper object at 0x1032b48e0>()]> cb=[_chain_future.<locals>._call_set_state() at /Users/k9/.pyenv/versions/3.9.11/lib/python3.9/asyncio/futures.py:391]>
2023-01-08 14:36:13,278 - py.warnings - WARNING - /Users/k9/.pyenv/versions/3.9.11/envs/kedro-on-aws/lib/python3.9/site-packages/kedro/framework/context/context.py:339: UserWarning: Credentials not found in your Kedro project config.
No files found in ['/Users/k9/kedro-on-aws/conf/base', '/Users/k9/kedro-on-aws/conf/local'] matching the glob pattern(s): ('credentials*', 'credentials*/**', '**/credentials*')
  warn(f"Credentials not found in your Kedro project config.\n{str(exc)}")

2023-01-08 14:36:13,452 - py.warnings - WARNING - /Users/k9/.pyenv/versions/3.9.11/envs/kedro-on-aws/lib/python3.9/site-packages/kedro/framework/project/__init__.py:330: UserWarning: An error occurred while importing the 'iris.pipeline' module. Nothing defined therein will be returned by 'find_pipelines'.

Traceback (most recent call last):
  File "/Users/k9/.pyenv/versions/3.9.11/envs/kedro-on-aws/lib/python3.9/site-packages/kedro/framework/project/__init__.py", line 327, in find_pipelines
    pipeline_module = importlib.import_module(pipeline_module_name)
  File "/Users/k9/.pyenv/versions/3.9.11/lib/python3.9/importlib/__init__.py", line 127, in import_module
    return _bootstrap._gcd_import(name[level:], package, level)
  File "<frozen importlib._bootstrap>", line 1030, in _gcd_import
  File "<frozen importlib._bootstrap>", line 1007, in _find_and_load
  File "<frozen importlib._bootstrap>", line 986, in _find_and_load_unlocked
  File "<frozen importlib._bootstrap>", line 680, in _load_unlocked
  File "<frozen importlib._bootstrap_external>", line 850, in exec_module
  File "<frozen importlib._bootstrap>", line 228, in _call_with_frames_removed
  File "/Users/k9/kedro-on-aws/src/iris/pipeline.py", line 8, in <module>
    from .nodes import make_predictions, report_accuracy, split_data
ImportError: cannot import name 'make_predictions' from 'iris.nodes' (/Users/k9/kedro-on-aws/src/iris/nodes.py)

  warnings.warn(

2023-01-08 14:36:16,870 - py.warnings - WARNING - /Users/k9/.pyenv/versions/3.9.11/envs/kedro-on-aws/lib/python3.9/site-packages/kedro/framework/context/context.py:339: UserWarning: Credentials not found in your Kedro project config.
No files found in ['/Users/k9/kedro-on-aws/conf/base', '/Users/k9/kedro-on-aws/conf/local'] matching the glob pattern(s): ('credentials*', 'credentials*/**', '**/credentials*')
  warn(f"Credentials not found in your Kedro project config.\n{str(exc)}")

2023-01-08 14:36:16,874 - kedro.ipython - INFO - Kedro project iris
2023-01-08 14:36:16,875 - kedro.ipython - INFO - Defined global variable 'context', 'session', 'catalog' and 'pipelines'
2023-01-08 14:36:16,889 - kedro.io.data_catalog - INFO - Loading data from 'transactions' (AthenaQueryDataSet)...
2023-01-08 14:37:05,970 - kedro.io.data_catalog - INFO - Loading data from 'transactions' (AthenaQueryDataSet)...
2023-01-08 14:37:09,642 - asyncio - ERROR - Task was destroyed but it is pending!
task: <Task pending name='Task-2' coro=<Kernel.poll_control_queue() running at /Users/k9/.pyenv/versions/3.9.11/envs/kedro-on-aws/lib/python3.9/site-packages/ipykernel/kernelbase.py:284> wait_for=<Future pending cb=[<TaskWakeupMethWrapper object at 0x107b7ef40>()]> cb=[_chain_future.<locals>._call_set_state() at /Users/k9/.pyenv/versions/3.9.11/lib/python3.9/asyncio/futures.py:391]>
2023-01-08 14:37:10,537 - py.warnings - WARNING - /Users/k9/.pyenv/versions/3.9.11/envs/kedro-on-aws/lib/python3.9/site-packages/kedro/framework/context/context.py:339: UserWarning: Credentials not found in your Kedro project config.
No files found in ['/Users/k9/kedro-on-aws/conf/base', '/Users/k9/kedro-on-aws/conf/local'] matching the glob pattern(s): ('credentials*', 'credentials*/**', '**/credentials*')
  warn(f"Credentials not found in your Kedro project config.\n{str(exc)}")

2023-01-08 14:37:10,714 - py.warnings - WARNING - /Users/k9/.pyenv/versions/3.9.11/envs/kedro-on-aws/lib/python3.9/site-packages/kedro/framework/project/__init__.py:330: UserWarning: An error occurred while importing the 'iris.pipeline' module. Nothing defined therein will be returned by 'find_pipelines'.

Traceback (most recent call last):
  File "/Users/k9/.pyenv/versions/3.9.11/envs/kedro-on-aws/lib/python3.9/site-packages/kedro/framework/project/__init__.py", line 327, in find_pipelines
    pipeline_module = importlib.import_module(pipeline_module_name)
  File "/Users/k9/.pyenv/versions/3.9.11/lib/python3.9/importlib/__init__.py", line 127, in import_module
    return _bootstrap._gcd_import(name[level:], package, level)
  File "<frozen importlib._bootstrap>", line 1030, in _gcd_import
  File "<frozen importlib._bootstrap>", line 1007, in _find_and_load
  File "<frozen importlib._bootstrap>", line 986, in _find_and_load_unlocked
  File "<frozen importlib._bootstrap>", line 680, in _load_unlocked
  File "<frozen importlib._bootstrap_external>", line 850, in exec_module
  File "<frozen importlib._bootstrap>", line 228, in _call_with_frames_removed
  File "/Users/k9/kedro-on-aws/src/iris/pipeline.py", line 8, in <module>
    from .nodes import make_predictions, report_accuracy, split_data
ImportError: cannot import name 'make_predictions' from 'iris.nodes' (/Users/k9/kedro-on-aws/src/iris/nodes.py)

  warnings.warn(

2023-01-08 14:37:13,794 - py.warnings - WARNING - /Users/k9/.pyenv/versions/3.9.11/envs/kedro-on-aws/lib/python3.9/site-packages/kedro/framework/context/context.py:339: UserWarning: Credentials not found in your Kedro project config.
No files found in ['/Users/k9/kedro-on-aws/conf/base', '/Users/k9/kedro-on-aws/conf/local'] matching the glob pattern(s): ('credentials*', 'credentials*/**', '**/credentials*')
  warn(f"Credentials not found in your Kedro project config.\n{str(exc)}")

2023-01-08 14:37:13,798 - kedro.ipython - INFO - Kedro project iris
2023-01-08 14:37:13,799 - kedro.ipython - INFO - Defined global variable 'context', 'session', 'catalog' and 'pipelines'
2023-01-08 14:37:13,814 - kedro.io.data_catalog - INFO - Loading data from 'transactions' (AthenaQueryDataSet)...
2023-01-08 14:37:19,103 - iris.extras.datasets.athena_dataset - INFO - Athena query output saved to: s3://k9-eth/athena-output/tables/f682721e-fed5-4599-b57b-1b69282e78ca
2023-01-08 14:37:27,409 - kedro.io.data_catalog - INFO - Loading data from 'transactions' (AthenaQueryDataSet)...
2023-01-08 15:02:10,238 - asyncio - ERROR - Task was destroyed but it is pending!
task: <Task pending name='Task-2' coro=<Kernel.poll_control_queue() running at /Users/k9/.pyenv/versions/3.9.11/envs/kedro-on-aws/lib/python3.9/site-packages/ipykernel/kernelbase.py:284> wait_for=<Future pending cb=[<TaskWakeupMethWrapper object at 0x10603fa60>()]> cb=[_chain_future.<locals>._call_set_state() at /Users/k9/.pyenv/versions/3.9.11/lib/python3.9/asyncio/futures.py:391]>
2023-01-08 15:02:11,339 - py.warnings - WARNING - /Users/k9/.pyenv/versions/3.9.11/envs/kedro-on-aws/lib/python3.9/site-packages/kedro/framework/context/context.py:339: UserWarning: Credentials not found in your Kedro project config.
No files found in ['/Users/k9/kedro-on-aws/conf/base', '/Users/k9/kedro-on-aws/conf/local'] matching the glob pattern(s): ('credentials*', 'credentials*/**', '**/credentials*')
  warn(f"Credentials not found in your Kedro project config.\n{str(exc)}")

2023-01-08 15:02:11,555 - py.warnings - WARNING - /Users/k9/.pyenv/versions/3.9.11/envs/kedro-on-aws/lib/python3.9/site-packages/kedro/framework/project/__init__.py:330: UserWarning: An error occurred while importing the 'iris.pipeline' module. Nothing defined therein will be returned by 'find_pipelines'.

Traceback (most recent call last):
  File "/Users/k9/.pyenv/versions/3.9.11/envs/kedro-on-aws/lib/python3.9/site-packages/kedro/framework/project/__init__.py", line 327, in find_pipelines
    pipeline_module = importlib.import_module(pipeline_module_name)
  File "/Users/k9/.pyenv/versions/3.9.11/lib/python3.9/importlib/__init__.py", line 127, in import_module
    return _bootstrap._gcd_import(name[level:], package, level)
  File "<frozen importlib._bootstrap>", line 1030, in _gcd_import
  File "<frozen importlib._bootstrap>", line 1007, in _find_and_load
  File "<frozen importlib._bootstrap>", line 986, in _find_and_load_unlocked
  File "<frozen importlib._bootstrap>", line 680, in _load_unlocked
  File "<frozen importlib._bootstrap_external>", line 850, in exec_module
  File "<frozen importlib._bootstrap>", line 228, in _call_with_frames_removed
  File "/Users/k9/kedro-on-aws/src/iris/pipeline.py", line 8, in <module>
    from .nodes import make_predictions, report_accuracy, split_data
ImportError: cannot import name 'make_predictions' from 'iris.nodes' (/Users/k9/kedro-on-aws/src/iris/nodes.py)

  warnings.warn(

2023-01-08 15:02:14,920 - py.warnings - WARNING - /Users/k9/.pyenv/versions/3.9.11/envs/kedro-on-aws/lib/python3.9/site-packages/kedro/framework/context/context.py:339: UserWarning: Credentials not found in your Kedro project config.
No files found in ['/Users/k9/kedro-on-aws/conf/base', '/Users/k9/kedro-on-aws/conf/local'] matching the glob pattern(s): ('credentials*', 'credentials*/**', '**/credentials*')
  warn(f"Credentials not found in your Kedro project config.\n{str(exc)}")

2023-01-08 15:02:14,924 - kedro.ipython - INFO - Kedro project iris
2023-01-08 15:02:14,925 - kedro.ipython - INFO - Defined global variable 'context', 'session', 'catalog' and 'pipelines'
2023-01-08 15:02:16,366 - kedro.io.data_catalog - INFO - Loading data from 'transactions' (AthenaQueryDataSet)...
2023-01-08 15:02:39,900 - asyncio - ERROR - Task was destroyed but it is pending!
task: <Task pending name='Task-1' coro=<Kernel.poll_control_queue() running at /Users/k9/.pyenv/versions/3.9.11/envs/kedro-on-aws/lib/python3.9/site-packages/ipykernel/kernelbase.py:284> wait_for=<Future pending cb=[<TaskWakeupMethWrapper object at 0x12f07ee50>()]> cb=[_chain_future.<locals>._call_set_state() at /Users/k9/.pyenv/versions/3.9.11/lib/python3.9/asyncio/futures.py:391]>
2023-01-08 15:02:40,814 - py.warnings - WARNING - /Users/k9/.pyenv/versions/3.9.11/envs/kedro-on-aws/lib/python3.9/site-packages/kedro/framework/context/context.py:339: UserWarning: Credentials not found in your Kedro project config.
No files found in ['/Users/k9/kedro-on-aws/conf/base', '/Users/k9/kedro-on-aws/conf/local'] matching the glob pattern(s): ('credentials*', 'credentials*/**', '**/credentials*')
  warn(f"Credentials not found in your Kedro project config.\n{str(exc)}")

2023-01-08 15:02:40,986 - py.warnings - WARNING - /Users/k9/.pyenv/versions/3.9.11/envs/kedro-on-aws/lib/python3.9/site-packages/kedro/framework/project/__init__.py:330: UserWarning: An error occurred while importing the 'iris.pipeline' module. Nothing defined therein will be returned by 'find_pipelines'.

Traceback (most recent call last):
  File "/Users/k9/.pyenv/versions/3.9.11/envs/kedro-on-aws/lib/python3.9/site-packages/kedro/framework/project/__init__.py", line 327, in find_pipelines
    pipeline_module = importlib.import_module(pipeline_module_name)
  File "/Users/k9/.pyenv/versions/3.9.11/lib/python3.9/importlib/__init__.py", line 127, in import_module
    return _bootstrap._gcd_import(name[level:], package, level)
  File "<frozen importlib._bootstrap>", line 1030, in _gcd_import
  File "<frozen importlib._bootstrap>", line 1007, in _find_and_load
  File "<frozen importlib._bootstrap>", line 986, in _find_and_load_unlocked
  File "<frozen importlib._bootstrap>", line 680, in _load_unlocked
  File "<frozen importlib._bootstrap_external>", line 850, in exec_module
  File "<frozen importlib._bootstrap>", line 228, in _call_with_frames_removed
  File "/Users/k9/kedro-on-aws/src/iris/pipeline.py", line 8, in <module>
    from .nodes import make_predictions, report_accuracy, split_data
ImportError: cannot import name 'make_predictions' from 'iris.nodes' (/Users/k9/kedro-on-aws/src/iris/nodes.py)

  warnings.warn(

2023-01-08 15:02:44,139 - py.warnings - WARNING - /Users/k9/.pyenv/versions/3.9.11/envs/kedro-on-aws/lib/python3.9/site-packages/kedro/framework/context/context.py:339: UserWarning: Credentials not found in your Kedro project config.
No files found in ['/Users/k9/kedro-on-aws/conf/base', '/Users/k9/kedro-on-aws/conf/local'] matching the glob pattern(s): ('credentials*', 'credentials*/**', '**/credentials*')
  warn(f"Credentials not found in your Kedro project config.\n{str(exc)}")

2023-01-08 15:02:44,143 - kedro.ipython - INFO - Kedro project iris
2023-01-08 15:02:44,144 - kedro.ipython - INFO - Defined global variable 'context', 'session', 'catalog' and 'pipelines'
2023-01-08 15:02:44,695 - kedro.io.data_catalog - INFO - Loading data from 'transactions' (AthenaQueryDataSet)...
2023-01-08 15:02:44,863 - iris.extras.datasets.athena_dataset - INFO - Attempt to create external table temp_tbl_6e6cd64021 with Athena CTAS query.
2023-01-08 15:02:50,035 - iris.extras.datasets.athena_dataset - INFO - Athena query output files saved to: s3://k9-eth/athena-output/tables/8c31f53a-353e-4153-90ab-b6bcfcc75515
